Workbook

Sheet Estimator
A1: Digital Acquisition Estimator - Switchboard SMS Cold Acquisition
A2: Enter your budget; the sheet returns minimum and high projections (net of fees, through election day) against your ROI floor.
A3: Legend: yellow + blue text = your inputs | black = calculated | green = pulled from another tab
A5: STEP 1 - BUDGET, ROI FLOOR & AUDIENCE
A6: Budget ($) | B6: 10000 | D6: Total you plan to invest (example value - replace with yours)
A7: Minimum ROI target | B7: 1.5 | D7: 150% ROI = every $1 spent must come back as $2.50 net by election day
A8: Cold contacts available to text | B8: 100000 | D8: Size of your textable cold list - you can't text more people than you have numbers for
A9: Months remaining until election day | B9: 3.5 | D9: Through Nov 3, 2026 - update as the cycle progresses; repeat giving stops at election day
A11: STEP 2 - SWITCHBOARD TEXTING COSTS
A12: Initial message type | B12: SMS - 2 segments (161-320 chars) | D12: Pick from the dropdown - rates on the Switchboard Rates tab
A13: Cost per initial message ($) | B13: =INDEX('Switchboard Rates'!$B$3:$B$6,MATCH($B$12,'Switchboard Rates'!$A$3:$A$6,0)) -> 0.03 | D13: Pulled from Switchboard Rates for the type chosen above
A14: Cost per follow-up message ($) | B14: ='Switchboard Rates'!$B$3 -> 0.015 | D14: Follow-ups costed as 1-segment SMS; edit on the Switchboard Rates tab
A15: Avg follow-up messages per responder | B15: 3 | D15: Conversation messages sent only to people who reply (inbound is free)
A16: List rental cost per contact ($) | B16: 0 | D16: 0 if texting numbers you already have; $0.02-$0.10 if renting/matching
A18: STEP 3 - PROCESSING FEES (revenue is counted NET of these)
A19: Payment processing fee | B19: 0.0395 | D19: ActBlue charges 3.95% per transaction (actblue.com; confirm your processor)
A20: Refund / failed payment rate | B20: 0.01 | D20: Assumption - share of gross donations refunded or failed; replace with your actual
A21: Net revenue factor | B21: =(1-$B$19)*(1-$B$20) -> 0.950895 | D21: Share of each gross dollar you keep
A23: STEP 4 - COLD FUNNEL ASSUMPTIONS (enter a conservative and an optimistic value)
B24: Minimum (low) | C24: High
A25: Delivery rate | B25: 0.93 | C25: 0.97 | D25: Share of sends reaching a phone (assumption - typical 93-97%)
A26: Response rate (of delivered) | B26: 0.01 | C26: 0.04 | D26: Assumption - cold lists typically 1-5%
A27: Donor conversion rate (of delivered) | B27: 0.0005 | C27: 0.003 | D27: Share of delivered texts producing a NEW donor. Assumption - cold SMS typically 0.05-0.3%. Replace with your blended rate from the Actuals Tracker
A28: Average initial donation ($) | B28: 25 | C28: 35 | D28: Assumption - cold small-dollar averages; replace with your actuals
A29: Repeat gifts per donor per month | B29: 0.1 | C29: 0.3 | D29: Assumption - how often a new donor gives again each month, scaled by months left in Step 1
A30: Average repeat gift ($) | B30: 25 | C30: 35 | D30: Assumption - average size of those follow-up gifts
A32: PROJECTIONS (net of processing fees, through election day)
B33: Minimum Projection | C33: High Projection
A34: All-in cost per contact ($) | B34: =$B$13+B25*B26*$B$15*$B$14+$B$16 -> 0.0304185 | C34: =$B$13+C25*C26*$B$15*$B$14+$B$16 -> 0.031746 | D34: Initial message + expected follow-ups (responders only) + list rental
A35: Contacts texted | B35: =IF(B34>0,MIN($B$8,ROUNDDOWN($B$6/B34,0)),0) -> 100000 | C35: =IF(C34>0,MIN($B$8,ROUNDDOWN($B$6/C34,0)),0) -> 100000 | D35: Lesser of what the budget buys and the list size
A36: Estimated program spend ($) | B36: =B35*B34 -> 3041.85 | C36: =C35*C34 -> 3174.6 | D36: Actual texting + acquisition cost (can be under budget if the list runs out first)
A37: Unspent budget ($) | B37: =$B$6-B36 -> 6958.15 | C37: =$B$6-C36 -> 6825.4
A38: Messages delivered | B38: =B35*B25 -> 93000 | C38: =C35*C25 -> 97000
A39: Conversations started (replies) | B39: =B38*B26 -> 930 | C39: =C38*C26 -> 3880
A40: New donors acquired | B40: =B38*B27 -> 46.5 | C40: =C38*C27 -> 291
A41: Cost per acquisition ($) | B41: =IF(B40>0,B36/B40,"n/a") -> 65.416129 | C41: =IF(C40>0,C36/C40,"n/a") -> 10.909278 | D41: Program spend / new donors
A42: Net immediate revenue - first gifts ($) | B42: =B40*B28*$B$21 -> 1105.4154 | C42: =C40*C28*$B$21 -> 9684.8656 | D42: After processing fees and refunds
A43: Net revenue through election day ($) | B43: =B40*B48 -> 1492.3108 | C43: =C40*C48 -> 19853.974 | D43: First gifts + repeat giving for the months remaining, net of fees
A44: ROI through election day (net) | B44: =IF(B36>0,(B43-B36)/B36,0) -> -0.50940683 | C44: =IF(C36>0,(C43-C36)/C36,0) -> 5.2540082 | D44: Return after acquisition + texting costs AND processing fees, on dollars actually spent
A45: Net revenue per $1 spent | B45: =IF(B36>0,B43/B36,0) -> 0.49059317 | C45: =IF(C36>0,C43/C36,0) -> 6.2540082
...

Sheet Switchboard Rates
A1: Switchboard Texting Rates (pay-as-you-go)
A2: Message type | B2: Cost per outbound message ($) | C2: Notes
A3: SMS - 1 segment (up to 160 chars) | B3: 0.015 | C3: Plain text, no media
A4: SMS - 2 segments (161-320 chars) | B4: 0.03 | C4: 2 x $0.015 per segment
A5: SMS - 3 segments (321-480 chars) | B5: 0.045 | C5: 3 x $0.015 per segment
A6: MMS (media attached / long message) | B6: 0.03 | C6: Flat rate - same as a 2-segment SMS
A8: Rates confirmed by campaign, 2026-07-23: $0.015 per SMS segment, $0.030 per MMS (pay-as-you-go; see welcome.oneswitchboard.com/pricing). No monthly fee, no setup fee, no minimums or prepayment; inbound replies, landline cleaning, and errored messages are free. Blue cells are editable if rates change - the Estimator pulls from this table. Follow-up conversation messages are costed at the SMS 1-segment rate (cell B3).

Sheet Actuals Tracker
A1: Actuals Tracker - log every blast, and your real rates replace the guesses
A2: Enter the shaded columns (A-I) after each send; rates on the right compute automatically. Row 5 is an EXAMPLE with made-up numbers - delete it before logging real sends. Once 2-3 real blasts are logged, copy the blended rates from the TOTALS row into Estimator Step 4.
A4: Date | B4: Blast name | C4: Sent | D4: Delivered | E4: Replies | F4: Opt-outs | G4: New Donors | H4: Gross Revenue ($) | I4: Cost ($) | J4: Delivery % | K4: Response % | L4: Conversion % | M4: Avg Gift ($) | N4: CPA ($) | O4: Net ROI
A5: 46223 | B5: EXAMPLE - launch blast (delete this row) | C5: 10000 | D5: 9400 | E5: 250 | F5: 120 | G5: 12 | H5: 380 | I5: 310 | J5: =IF($C5>0,$D5/$C5,"") -> 0.94 | K5: =IF($D5>0,$E5/$D5,"") -> 0.026595745 | L5: =IF($D5>0,$G5/$D5,"") -> 0.0012765957 | M5: =IF($G5>0,$H5/$G5,"") -> 31.666667 | N5: =IF($G5>0,$I5/$G5,"") -> 25.833333 | O5: =IF($I5>0,($H5*Estimator!$B$21-$I5)/$I5,"") -> 0.16561323
J6: =IF($C6>0,$D6/$C6,"") | K6: =IF($D6>0,$E6/$D6,"") | L6: =IF($D6>0,$G6/$D6,"") | M6: =IF($G6>0,$H6/$G6,"") | N6: =IF($G6>0,$I6/$G6,"") | O6: =IF($I6>0,($H6*Estimator!$B$21-$I6)/$I6,"")
J7: =IF($C7>0,$D7/$C7,"") | K7: =IF($D7>0,$E7/$D7,"") | L7: =IF($D7>0,$G7/$D7,"") | M7: =IF($G7>0,$H7/$G7,"") | N7: =IF($G7>0,$I7/$G7,"") | O7: =IF($I7>0,($H7*Estimator!$B$21-$I7)/$I7,"")
J8: =IF($C8>0,$D8/$C8,"") | K8: =IF($D8>0,$E8/$D8,"") | L8: =IF($D8>0,$G8/$D8,"") | M8: =IF($G8>0,$H8/$G8,"") | N8: =IF($G8>0,$I8/$G8,"") | O8: =IF($I8>0,($H8*Estimator!$B$21-$I8)/$I8,"")
J9: =IF($C9>0,$D9/$C9,"") | K9: =IF($D9>0,$E9/$D9,"") | L9: =IF($D9>0,$G9/$D9,"") | M9: =IF($G9>0,$H9/$G9,"") | N9: =IF($G9>0,$I9/$G9,"") | O9: =IF($I9>0,($H9*Estimator!$B$21-$I9)/$I9,"")
J10: =IF($C10>0,$D10/$C10,"") | K10: =IF($D10>0,$E10/$D10,"") | L10: =IF($D10>0,$G10/$D10,"") | M10: =IF($G10>0,$H10/$G10,"") | N10: =IF($G10>0,$I10/$G10,"") | O10: =IF($I10>0,($H10*Estimator!$B$21-$I10)/$I10,"")
J11: =IF($C11>0,$D11/$C11,"") | K11: =IF($D11>0,$E11/$D11,"") | L11: =IF($D11>0,$G11/$D11,"") | M11: =IF($G11>0,$H11/$G11,"") | N11: =IF($G11>0,$I11/$G11,"") | O11: =IF($I11>0,($H11*Estimator!$B$21-$I11)/$I11,"")
J12: =IF($C12>0,$D12/$C12,"") | K12: =IF($D12>0,$E12/$D12,"") | L12: =IF($D12>0,$G12/$D12,"") | M12: =IF($G12>0,$H12/$G12,"") | N12: =IF($G12>0,$I12/$G12,"") | O12: =IF($I12>0,($H12*Estimator!$B$21-$I12)/$I12,"")
J13: =IF($C13>0,$D13/$C13,"") | K13: =IF($D13>0,$E13/$D13,"") | L13: =IF($D13>0,$G13/$D13,"") | M13: =IF($G13>0,$H13/$G13,"") | N13: =IF($G13>0,$I13/$G13,"") | O13: =IF($I13>0,($H13*Estimator!$B$21-$I13)/$I13,"")
J14: =IF($C14>0,$D14/$C14,"") | K14: =IF($D14>0,$E14/$D14,"") | L14: =IF($D14>0,$G14/$D14,"") | M14: =IF($G14>0,$H14/$G14,"") | N14: =IF($G14>0,$I14/$G14,"") | O14: =IF($I14>0,($H14*Estimator!$B$21-$I14)/$I14,"")
J15: =IF($C15>0,$D15/$C15,"") | K15: =IF($D15>0,$E15/$D15,"") | L15: =IF($D15>0,$G15/$D15,"") | M15: =IF($G15>0,$H15/$G15,"") | N15: =IF($G15>0,$I15/$G15,"") | O15: =IF($I15>0,($H15*Estimator!$B$21-$I15)/$I15,"")
J16: =IF($C16>0,$D16/$C16,"") | K16: =IF($D16>0,$E16/$D16,"") | L16: =IF($D16>0,$G16/$D16,"") | M16: =IF($G16>0,$H16/$G16,"") | N16: =IF($G16>0,$I16/$G16,"") | O16: =IF($I16>0,($H16*Estimator!$B$21-$I16)/$I16,"")
J17: =IF($C17>0,$D17/$C17,"") | K17: =IF($D17>0,$E17/$D17,"") | L17: =IF($D17>0,$G17/$D17,"") | M17: =IF($G17>0,$H17/$G17,"") | N17: =IF($G17>0,$I17/$G17,"") | O17: =IF($I17>0,($H17*Estimator!$B$21-$I17)/$I17,"")
... J19: =IF($C19>0,$D19/$C19,"") | K19: =IF($D19>0,$E19/$D19,"") | L19: =IF($D19>0,$G19/$D19,"") | M19: =IF($G19>0,$H19/$G19,"") | N19: =IF($G19>0,$I19/$G19,"") | O19: =IF($I19>0,($H19*Estimator!$B$21-$I19)/$I19,"")
B20: TOTALS / BLENDED RATES | C20: =SUM(C5:C19) -> 10000 | D20: =SUM(D5:D19) -> 9400 | E20: =SUM(E5:E19) -> 250 | F20: =SUM(F5:F19) -> 120 | G20: =SUM(G5:G19) -> 12 | H20: =SUM(H5:H19) -> 380 | I20: =SUM(I5:I19) -> 310 | J20: =IF($C20>0,$D20/$C20,"") -> 0.94 | K20: =IF($D20>0,$E20/$D20,"") -> 0.026595745 | L20: =IF($D20>0,$G20/$D20,"") -> 0.0012765957 | M20: =IF($G20>0,$H20/$G20,"") -> 31.666667 | N20: =IF($G20>0,$I20/$G20,"") -> 25.833333 | O20: =IF($I20>0,($H20*Estimator!$B$21-$I20)/$I20,"") -> 0.16561323
A22: Net ROI here uses the net revenue factor from Estimator Step 3 (processing fees + refunds) and each blast's actual cost. Opt-outs shrink your future textable list - subtract the running total from 'Cold contacts available' on the Estimator tab.

Sheet Scenarios
A1: Budget Scenarios - Minimum vs. High
A2: Same assumptions as the Estimator tab at different budget levels, net of fees, through election day. Blue budgets are editable. Spend stops growing once the budget can text the whole list.
B4: Minimum Projection | F4: High Projection
A5: Budget ($) | B5: Spend ($) | C5: New Donors | D5: CPA ($) | E5: Net ROI | F5: Spend ($) | G5: New Donors | H5: CPA ($) | I5: Net ROI | J5: Meets Target? (min)
A6: 1000 | B6: =(IF(Estimator!$B$34>0,MIN(Estimator!$B$8,ROUNDDOWN($A6/Estimator!$B$34,0)),0))*Estimator!$B$34 -> 999.97777 | C6: =(IF(Estimator!$B$34>0,MIN(Estimator!$B$8,ROUNDDOWN($A6/Estimator!$B$34,0)),0))*Estimator!$B$25*Estimator!$B$27 -> 15.28641 | D6: =IF(C6>0,B6/C6,"n/a") -> 65.416129 | E6: =IF(B6>0,(C6*Estimator!$B$48-B6)/B6,0) -> -0.50940683 | F6: =(IF(Estimator!$C$34>0,MIN(Estimator!$B$8,ROUNDDOWN($A6/Estimator!$C$34,0)),0))*Estimator!$C$34 -> 999.999 | G6: =(IF(Estimator!$C$34>0,MIN(Estimator!$B$8,ROUNDDOWN($A6/Estimator!$C$34,0)),0))*Estimator!$C$25*Estimator!$C$27 -> 91.665 | H6: =IF(G6>0,F6/G6,"n/a") -> 10.909278 | I6: =IF(F6>0,(G6*Estimator!$C$48-F6)/F6,0) -> 5.2540082 | J6: =IF(E6>=Estimator!$B$7,"MEETS TARGET","BELOW TARGET") -> BELOW TARGET
A7: 2500 | B7: =(IF(Estimator!$B$34>0,MIN(Estimator!$B$8,ROUNDDOWN($A7/Estimator!$B$34,0)),0))*Estimator!$B$34 -> 2499.9748 | C7: =(IF(Estimator!$B$34>0,MIN(Estimator!$B$8,ROUNDDOWN($A7/Estimator!$B$34,0)),0))*Estimator!$B$25*Estimator!$B$27 -> 38.21649 | D7: =IF(C7>0,B7/C7,"n/a") -> 65.416129 | E7: =IF(B7>0,(C7*Estimator!$B$48-B7)/B7,0) -> -0.50940683 | F7: =(IF(Estimator!$C$34>0,MIN(Estimator!$B$8,ROUNDDOWN($A7/Estimator!$C$34,0)),0))*Estimator!$C$34 -> 2499.9975 | G7: =(IF(Estimator!$C$34>0,MIN(Estimator!$B$8,ROUNDDOWN($A7/Estimator!$C$34,0)),0))*Estimator!$C$25*Estimator!$C$27 -> 229.1625 | H7: =IF(G7>0,F7/G7,"n/a") -> 10.909278 | I7: =IF(F7>0,(G7*Estimator!$C$48-F7)/F7,0) -> 5.2540082 | J7: =IF(E7>=Estimator!$B$7,"MEETS TARGET","BELOW TARGET") -> BELOW TARGET
A8: 5000 | B8: =(IF(Estimator!$B$34>0,MIN(Estimator!$B$8,ROUNDDOWN($A8/Estimator!$B$34,0)),0))*Estimator!$B$34 -> 3041.85 | C8: =(IF(Estimator!$B$34>0,MIN(Estimator!$B$8,ROUNDDOWN($A8/Estimator!$B$34,0)),0))*Estimator!$B$25*Estimator!$B$27 -> 46.5 | D8: =IF(C8>0,B8/C8,"n/a") -> 65.416129 | E8: =IF(B8>0,(C8*Estimator!$B$48-B8)/B8,0) -> -0.50940683 | F8: =(IF(Estimator!$C$34>0,MIN(Estimator!$B$8,ROUNDDOWN($A8/Estimator!$C$34,0)),0))*Estimator!$C$34 -> 3174.6 | G8: =(IF(Estimator!$C$34>0,MIN(Estimator!$B$8,ROUNDDOWN($A8/Estimator!$C$34,0)),0))*Estimator!$C$25*Estimator!$C$27 -> 291 | H8: =IF(G8>0,F8/G8,"n/a") -> 10.909278 | I8: =IF(F8>0,(G8*Estimator!$C$48-F8)/F8,0) -> 5.2540082 | J8: =IF(E8>=Estimator!$B$7,"MEETS TARGET","BELOW TARGET") -> BELOW TARGET
A9: 10000 | B9: =(IF(Estimator!$B$34>0,MIN(Estimator!$B$8,ROUNDDOWN($A9/Estimator!$B$34,0)),0))*Estimator!$B$34 -> 3041.85 | C9: =(IF(Estimator!$B$34>0,MIN(Estimator!$B$8,ROUNDDOWN($A9/Estimator!$B$34,0)),0))*Estimator!$B$25*Estimator!$B$27 -> 46.5 | D9: =IF(C9>0,B9/C9,"n/a") -> 65.416129 | E9: =IF(B9>0,(C9*Estimator!$B$48-B9)/B9,0) -> -0.50940683 | F9: =(IF(Estimator!$C$34>0,MIN(Estimator!$B$8,ROUNDDOWN($A9/Estimator!$C$34,0)),0))*Estimator!$C$34 -> 3174.6 | G9: =(IF(Estimator!$C$34>0,MIN(Estimator!$B$8,ROUNDDOWN($A9/Estimator!$C$34,0)),0))*Estimator!$C$25*Estimator!$C$27 -> 291 | H9: =IF(G9>0,F9/G9,"n/a") -> 10.909278 | I9: =IF(F9>0,(G9*Estimator!$C$48-F9)/F9,0) -> 5.2540082 | J9: =IF(E9>=Estimator!$B$7,"MEETS TARGET","BELOW TARGET") -> BELOW TARGET
A10: 25000 | B10: =(IF(Estimator!$B$34>0,MIN(Estimator!$B$8,ROUNDDOWN($A10/Estimator!$B$34,0)),0))*Estimator!$B$34 -> 3041.85 | C10: =(IF(Estimator!$B$34>0,MIN(Estimator!$B$8,ROUNDDOWN($A10/Estimator!$B$34,0)),0))*Estimator!$B$25*Estimator!$B$27 -> 46.5 | D10: =IF(C10>0,B10/C10,"n/a") -> 65.416129 | E10: =IF(B10>0,(C10*Estimator!$B$48-B10)/B10,0) -> -0.50940683 | F10: =(IF(Estimator!$C$34>0,MIN(Estimator!$B$8,ROUNDDOWN($A10/Estimator!$C$34,0)),0))*Estimator!$C$34 -> 3174.6 | G10: =(IF(Estimator!$C$34>0,MIN(Estimator!$B$8,ROUNDDOWN($A10/Estimator!$C$34,0)),0))*Estimator!$C$25*Estimator!$C$27 -> 291 | H10: =IF(G10>0,F10/G10,"n/a") -> 10.909278 | I10: =IF(F10>0,(G10*Estimator!$C$48-F10)/F10,0) -> 5.2540082 | J10: =IF(E10>=Estimator!$B$7,"MEETS TARGET","BELOW TARGET") -> BELOW TARGET
A11: 50000 | B11: =(IF(Estimator!$B$34>0,MIN(Estimator!$B$8,ROUNDDOWN($A11/Estimator!$B$34,0)),0))*Estimator!$B$34 -> 3041.85 | C11: =(IF(Estimator!$B$34>0,MIN(Estimator!$B$8,ROUNDDOWN($A11/Estimator!$B$34,0)),0))*Estimator!$B$25*Estimator!$B$27 -> 46.5 | D11: =IF(C11>0,B11/C11,"n/a") -> 65.416129 | E11: =IF(B11>0,(C11*Estimator!$B$48-B11)/B11,0) -> -0.50940683 | F11: =(IF(Estimator!$C$34>0,MIN(Estimator!$B$8,ROUNDDOWN($A11/Estimator!$C$34,0)),0))*Estimator!$C$34 -> 3174.6 | G11: =(IF(Estimator!$C$34>0,MIN(Estimator!$B$8,ROUNDDOWN($A11/Estimator!$C$34,0)),0))*Estimator!$C$25*Estimator!$C$27 -> 291 | H11: =IF(G11>0,F11/G11,"n/a") -> 10.909278 | I11: =IF(F11>0,(G11*Estimator!$C$48-F11)/F11,0) -> 5.2540082 | J11: =IF(E11>=Estimator!$B$7,"MEETS TARGET","BELOW TARGET") -> BELOW TARGET
A13: 'Meets Target?' checks the MINIMUM projection's net ROI against the floor on the Estimator tab - if even the conservative case clears it, the budget level is safe. ROI is computed on actual spend, so budgets larger than the list can absorb show flat results with the remainder unspent.
